{"name": "Cannot update the integer param of \"number_of_done_iterations_to_show\" of project with extreme values -- @1.2 ", "status": "failed", "statusDetails": {"message": "compare.UnmetExpectation: Expected 400 to equal 500\n", "trace": "  File \"c:\\users\\administrator\\appdata\\local\\programs\\python\\python37\\lib\\site-packages\\behave\\model.py\", line 1329, in run\n    match.run(runner.context)\n  File \"c:\\users\\administrator\\appdata\\local\\programs\\python\\python37\\lib\\site-packages\\behave\\matchers.py\", line 98, in run\n    self.func(context, *args, **kwargs)\n  File \"features\\steps\\project_steps.py\", line 41, in step_impl\n    expect(int(status_code)).to_equal(context.response.status_code)\n  File \"c:\\users\\administrator\\appdata\\local\\programs\\python\\python37\\lib\\site-packages\\compare.py\", line 173, in to_equal\n    ensure(self.value == other, True, message)\n  File \"c:\\users\\administrator\\appdata\\local\\programs\\python\\python37\\lib\\site-packages\\compare.py\", line 151, in ensure\n    raise UnmetExpectation(message)\n"}, "steps": [{"name": "Given I set up a \"PUT\" request to \"/projects/{proj_id}\" endpoint", "status": "passed", "start": 1556562460123, "stop": 1556562460125}, {"name": "And I set up the data", "status": "passed", "attachments": [{"name": ".text", "source": "116ec56f-2ab0-4985-8b51-2eadc4d8f953-attachment.txt", "type": "text/plain"}], "start": 1556562460125, "stop": 1556562460128}, {"name": "When I send the request", "status": "passed", "start": 1556562460129, "stop": 1556562460694}, {"name": "Then I get a \"400\" status code as response", "status": "failed", "statusDetails": {"message": "compare.UnmetExpectation: Expected 400 to equal 500\n", "trace": "  File \"c:\\users\\administrator\\appdata\\local\\programs\\python\\python37\\lib\\site-packages\\behave\\model.py\", line 1329, in run\n    match.run(runner.context)\n  File \"c:\\users\\administrator\\appdata\\local\\programs\\python\\python37\\lib\\site-packages\\behave\\matchers.py\", line 98, in run\n    self.func(context, *args, **kwargs)\n  File \"features\\steps\\project_steps.py\", line 41, in step_impl\n    expect(int(status_code)).to_equal(context.response.status_code)\n  File \"c:\\users\\administrator\\appdata\\local\\programs\\python\\python37\\lib\\site-packages\\compare.py\", line 173, in to_equal\n    ensure(self.value == other, True, message)\n  File \"c:\\users\\administrator\\appdata\\local\\programs\\python\\python37\\lib\\site-packages\\compare.py\", line 151, in ensure\n    raise UnmetExpectation(message)\n"}, "start": 1556562460694, "stop": 1556562460698}, {"name": "And I verify the general_problem of error is: \"The number is exceeded the limit of integers\"", "status": "skipped", "start": 1556562460699, "stop": 1556562460699}], "parameters": [{"name": "number", "value": "2147483648"}, {"name": "message", "value": "The number is exceeded the limit of integers"}], "start": 1556562460118, "stop": 1556562460699, "uuid": "f72e01b7-249c-41f1-ad63-2c60979db2bd", "historyId": "eb0a39a05740a3418acb732cfd60aea9", "labels": [{"name": "tag", "value": "negative"}, {"name": "tag", "value": "project"}, {"name": "severity", "value": "normal"}, {"name": "feature", "value": "Functional Test Negative Cases of Update Projects"}, {"name": "framework", "value": "behave"}, {"name": "language", "value": "cpython3"}]}